Workbook

Sheet Dashboard
A1: STICE FAMILY FINANCIAL DASHBOARD
A3: STRATEGIC STATUS
A4: Metric | B4: Value
A5: Combined Gross Income | B5: =Assumptions!B16+Assumptions!B24 -> 262000
A6: Combined Net Income | B6: =(Assumptions!B16*0.7)+(Assumptions!B24*0.75) -> 186000
A7: Annual Expenses (Budget) | B7: =(Assumptions!B35+Assumptions!B36+Assumptions!B37+Assumptions!B38+Assumptions!B39+Assumptions!B40+Assumptions!B41)*12 -> 197088
A8: Annual Free Cash Flow | B8: =B6-B7 -> -11088
A9: Monthly FCF | B9: =B8/12 -> -924
A10: Savings Rate | B10: =B8/B6 -> -0.059612903
A12: KEY STRATEGIC QUESTIONS
A13: Can we afford current lifestyle? | B13: =IF(B8>0,"YES - $"&TEXT(B9,"#,##0")&"/mo surplus","NO - $"&TEXT(ABS(B9),"#,##0")&"/mo deficit") -> NO - $924/mo deficit
A14: Runway if James venture fails? | B14: =IF(B8>50000,"3+ years","Review assumptions") -> Review assumptions
A15: Can we afford baby + house? | B15: =IF(B6-B7-2700*12>0,"YES","TIGHT") -> TIGHT
A17: ACTUAL PERFORMANCE | B17: =CONCATENATE("Period: ",TEXT(Config!B6,"MMM DD"),"-",TEXT(Config!B7,"MMM DD")) -> Period: Oct 30-Jan 28
A18: Metric | B18: Period Total | C18: Monthly Avg | D18: Status
A19: Total Income | B19: =SUMIFS('Raw Data'!G3:G10000,'Raw Data'!G3:G10000,">0",'Raw Data'!A3:A10000,">="&Config!B6,'Raw Data'!A3:A10000,"<="&Config!B7,'Raw Data'!J3:J10000,"") -> 267041.08 | C19: =B19/Config!$B$9 -> 89013.693
A20: Total Expenses | B20: =ABS(SUMIFS('Raw Data'!G3:G10000,'Raw Data'!G3:G10000,"<0",'Raw Data'!A3:A10000,">="&Config!B6,'Raw Data'!A3:A10000,"<="&Config!B7,'Raw Data'!J3:J10000,"")) -> 197546.32 | C20: =B20/Config!$B$9 -> 65848.773
A21: Net Cash Flow | B21: =B19-B20 -> 69494.76 | C21: =C19-C20 -> 23164.92 | D21: =IF(B21>0,"✓ Positive","⚠ Negative") -> ✓ Positive
A22: Savings Rate | B22: =IF(B19>0,B21/B19,0) -> 0.26023996 | D22: =IF(B22>=0.2,"✓ On Track","⚠ Below Target") -> ✓ On Track
A24: TOP SPENDING CATEGORIES (Monthly Avg)
A25: Category | B25: Actual/Mo | C25: Budget/Mo | D25: Variance | E25: Status
A26: Groceries | B26: =ABS(SUMIFS('Raw Data'!G3:G10000,'Raw Data'!C3:C10000,"Groceries",'Raw Data'!G3:G10000,"<0",'Raw Data'!A3:A10000,">="&Config!B6,'Raw Data'!A3:A10000,"<="&Config!B7,'Raw Data'!J3:J10000,""))/Config!$B$9 -> 1999.5867 | C26: =Config!B31 -> 2000 | D26: =C26-B26 -> 0.41333333 | E26: =IF(D26<0,"⚠ OVER","✓ OK") -> ✓ OK
A27: Shopping | B27: =ABS(SUMIFS('Raw Data'!G3:G10000,'Raw Data'!C3:C10000,"Shopping",'Raw Data'!G3:G10000,"<0",'Raw Data'!A3:A10000,">="&Config!B6,'Raw Data'!A3:A10000,"<="&Config!B7,'Raw Data'!J3:J10000,""))/Config!$B$9 -> 3382.5133 | C27: =Config!B33 -> 2500 | D27: =C27-B27 -> -882.51333 | E27: =IF(D27<0,"⚠ OVER","✓ OK") -> ⚠ OVER
A28: Restaurants & Bars | B28: =ABS(SUMIFS('Raw Data'!G3:G10000,'Raw Data'!C3:C10000,"Restaurants & Bars",'Raw Data'!G3:G10000,"<0",'Raw Data'!A3:A10000,">="&Config!B6,'Raw Data'!A3:A10000,"<="&Config!B7,'Raw Data'!J3:J10000,""))/Config!$B$9 -> 1057.7567 | C28: =Config!B32 -> 800 | D28: =C28-B28 -> -257.75667 | E28: =IF(D28<0,"⚠ OVER","✓ OK") -> ⚠ OVER
A29: Amazon (Merchant) | B29: =ABS(SUMIFS('Raw Data'!G3:G10000,'Raw Data'!B3:B10000,"*Amazon*",'Raw Data'!G3:G10000,"<0",'Raw Data'!A3:A10000,">="&Config!B6,'Raw Data'!A3:A10000,"<="&Config!B7,'Raw Data'!J3:J10000,""))/Config!$B$9 -> 1404.5367 | C29: =Config!E31 -> 1000 | D29: =C29-B29 -> -404.53667 | E29: =IF(D29<0,"⚠ OVER","✓ OK") -> ⚠ OVER
A31: NEXT ACTIONS
A32: 1. Update Assumptions sheet with actual account balances
A33: 2. Track Laura's actual billable hours monthly
A34: 3. Review Budget vs Actual for category deep-dives
A35: 4. Update Config dates for new analysis periods

Sheet Assumptions
A1: STICE FAMILY FINANCIAL MODEL - ASSUMPTIONS
A2: All blue cells are inputs. Changes flow through entire model.
A4: LAURA - EVOLVE FAMILY LAW PARTNER
A5: Driver | B5: Value | C5: Notes
A6: Base/Draw | B6: 120000 | C6: Guaranteed monthly draw annualized
A7: Target Billable Hours/Year | B7: 1200 | C7: Hours
A8: Effective Hourly Rate | B8: 350 | C8: Blended rate after realization
A9: Realization Rate | B9: 0.85 | C9: Collections / Billings
A10: Origination Bonus Rate | B10: 0.3 | C10: On new business brought in
A11: Estimated Originations | B11: 300000 | C11: New client business/year
A13: CALCULATED INCOME
A14: Billable Revenue | B14: =B7*B8*B9 -> 357000
A15: Origination Bonus | B15: =B10*B11 -> 90000 | D15: 2026 | E15: 2027 | F15: 2028 | G15: 2029 | H15: 2030
A16: Total Gross Compensation | B16: =B6+B15 -> 210000 | D16: =B16 -> 210000 | E16: 240000 | F16: 260000 | G16: 280000 | H16: 300000
A17: Est. Effective Tax Rate | B17: 0.3 | D17: =$B17 -> 0.3 | E17: =$B17 -> 0.3 | F17: =$B17 -> 0.3 | G17: =$B17 -> 0.3 | H17: =$B17 -> 0.3
A18: Est. Taxes & Deductions | B18: =B16*B17 -> 63000 | D18: =D16*D17 -> 63000 | E18: =E16*E17 -> 72000 | F18: =F16*F17 -> 78000 | G18: =G16*G17 -> 84000 | H18: =H16*H17 -> 90000
A19: Laura Net Take-Home | B19: =B16-B18 -> 147000 | D19: =D16-D18 -> 147000 | E19: =E16-E18 -> 168000 | F19: =F16-F18 -> 182000 | G19: =G16-G18 -> 196000 | H19: =H16-H18 -> 210000
A22: JAMES - CURRENT + VENTURE
A23: Driver | B23: Value | C23: Notes
A24: Current Passive Income | B24: 52000 | C24: Ep Atlanta
A25: Venture Revenue - Year 1 | B25: 0 | C25: New company
A26: Venture Revenue - Year 2 | B26: 0
A27: Venture Revenue - Year 3 | B27: 0 | C27: Low scenario
A28: Venture Revenue - Year 4 | B28: 0 | C28: Building
A29: Venture Revenue - Year 5 | B29: 0 | C29: Base case target
A30: Venture Tax Rate | B30: 0.25 | C30: Self-employment + income
A33: EXPENSE ASSUMPTIONS
A34: Category | B34: Monthly | C34: Notes
A35: Housing - Morningside P&I | B35: 4692 | C35: Fixed 30yr
A36: Housing - Tax/Ins/HOA Monthly | B36: 1827 | C36: Will increase ~3%/yr
A37: Student Loans Monthly | B37: 1024 | C37: Aidvantage
A38: Auto Payment Monthly | B38: 681 | C38: Lease
A39: Childcare Monthly (Baby, May 2027) | B39: 2200 | C39: Estimate
A40: Groceries Monthly | B40: 2000 | C40: Target
A41: All Other Monthly | B41: 4000 | C41: Discretionary + misc
A42: Annual Inflation Rate | B42: 0.03 | C42: For projections
A45: BALANCE SHEET ASSUMPTIONS
A46: Item | B46: Value | C46: Notes
A47: Rawlins Sale Net Proceeds | B47: 300000 | C47: April 2026
A48: Current Liquid Assets | B48: 80000 | C48: Cash + brokerage
...

Sheet 5-Year Pro Forma
A1: STICE FAMILY 5-YEAR FINANCIAL PROJECTION
B3: 2026 | C3: 2027 | D3: 2028 | E3: 2029 | F3: 2030
A4: REVENUE
A5: Laura - Gross Comp | B5: =Assumptions!D16 -> 210000 | C5: =Assumptions!E16 -> 240000 | D5: =Assumptions!F16 -> 260000 | E5: =Assumptions!G16 -> 280000 | F5: =Assumptions!H16 -> 300000
A6: James - Passive (Ep Atlanta) | B6: =Assumptions!$B$24 -> 52000 | C6: =Assumptions!$B$24 -> 52000 | D6: =Assumptions!$B$24 -> 52000 | E6: =Assumptions!$B$24 -> 52000 | F6: =Assumptions!$B$24 -> 52000
A7: James - Venture | B7: =Assumptions!$B$25 -> 0 | C7: =Assumptions!$B$26 -> 0 | D7: =Assumptions!$B$27 -> 0 | E7: =Assumptions!$B$28 -> 0 | F7: =Assumptions!$B$29 -> 0
A8: TOTAL GROSS REVENUE | B8: =SUM(B5:B7) -> 262000 | C8: =SUM(C5:C7) -> 292000 | D8: =SUM(D5:D7) -> 312000 | E8: =SUM(E5:E7) -> 332000 | F8: =SUM(F5:F7) -> 352000
A10: TAXES
A11: Laura - Est. Taxes (30%) | B11: =B5*0.3 -> 63000 | C11: =C5*0.3 -> 72000 | D11: =D5*0.3 -> 78000 | E11: =E5*0.3 -> 84000 | F11: =F5*0.3 -> 90000
A12: James - Est. Taxes (25%) | B12: =(B6+B7)*0.25 -> 13000 | C12: =(C6+C7)*0.25 -> 13000 | D12: =(D6+D7)*0.25 -> 13000 | E12: =(E6+E7)*0.25 -> 13000 | F12: =(F6+F7)*0.25 -> 13000
A13: TOTAL TAXES | B13: =B11+B12 -> 76000 | C13: =C11+C12 -> 85000 | D13: =D11+D12 -> 91000 | E13: =E11+E12 -> 97000 | F13: =F11+F12 -> 103000
A14: NET INCOME (After Tax) | B14: =B8-B13 -> 186000 | C14: =C8-C13 -> 207000 | D14: =D8-D13 -> 221000 | E14: =E8-E13 -> 235000 | F14: =F8-F13 -> 249000
A16: OPERATING EXPENSES
A17: Housing (P&I) | B17: =Assumptions!$B$35*12 -> 56304 | C17: =Assumptions!$B$35*12 -> 56304 | D17: =Assumptions!$B$35*12 -> 56304 | E17: =Assumptions!$B$35*12 -> 56304 | F17: =Assumptions!$B$35*12 -> 56304
A18: Housing (Tax/Ins/HOA) | B18: =Assumptions!$B$36*12*(1+Assumptions!$B$42)^0 -> 21924 | C18: =Assumptions!$B$36*12*(1+Assumptions!$B$42)^1 -> 22581.72 | D18: =Assumptions!$B$36*12*(1+Assumptions!$B$42)^2 -> 23259.172 | E18: =Assumptions!$B$36*12*(1+Assumptions!$B$42)^3 -> 23956.947 | F18: =Assumptions!$B$36*12*(1+Assumptions!$B$42)^4 -> 24675.655
A19: Student Loans | B19: =Assumptions!$B$37*12 -> 12288 | C19: =Assumptions!$B$37*12 -> 12288 | D19: =Assumptions!$B$37*12 -> 12288 | E19: =Assumptions!$B$37*12 -> 12288 | F19: =Assumptions!$B$37*12 -> 12288
A20: Auto | B20: =Assumptions!$B$38*12 -> 8172 | C20: =Assumptions!$B$38*12 -> 8172 | D20: =Assumptions!$B$38*12 -> 8172 | E20: =Assumptions!$B$38*12 -> 8172 | F20: =Assumptions!$B$38*12 -> 8172
A21: Childcare | B21: =Assumptions!$B$39*6 -> 13200 | C21: =Assumptions!$B$39*12 -> 26400 | D21: =Assumptions!$B$39*12*(1+Assumptions!$B$42)^1 -> 27192 | E21: =Assumptions!$B$39*12*(1+Assumptions!$B$42)^2 -> 28007.76 | F21: =Assumptions!$B$39*12*(1+Assumptions!$B$42)^3 -> 28847.993
A22: Groceries | B22: =Assumptions!$B$40*12*(1+Assumptions!$B$42)^0 -> 24000 | C22: =Assumptions!$B$40*12*(1+Assumptions!$B$42)^1 -> 24720 | D22: =Assumptions!$B$40*12*(1+Assumptions!$B$42)^2 -> 25461.6 | E22: =Assumptions!$B$40*12*(1+Assumptions!$B$42)^3 -> 26225.448 | F22: =Assumptions!$B$40*12*(1+Assumptions!$B$42)^4 -> 27012.211
A23: All Other | B23: =Assumptions!$B$41*12*(1+Assumptions!$B$42)^0 -> 48000 | C23: =Assumptions!$B$41*12*(1+Assumptions!$B$42)^1 -> 49440 | D23: =Assumptions!$B$41*12*(1+Assumptions!$B$42)^2 -> 50923.2 | E23: =Assumptions!$B$41*12*(1+Assumptions!$B$42)^3 -> 52450.896 | F23: =Assumptions!$B$41*12*(1+Assumptions!$B$42)^4 -> 54024.423
A24: TOTAL EXPENSES | B24: =B17+B18+B19+B20+B21+B22+B23 -> 183888 | C24: =C17+C18+C19+C20+C21+C22+C23 -> 199905.72 | D24: =D17+D18+D19+D20+D21+D22+D23 -> 203599.97 | E24: =E17+E18+E19+E20+E21+E22+E23 -> 207405.05 | F24: =F17+F18+F19+F20+F21+F22+F23 -> 211324.28
A26: FREE CASH FLOW | B26: =B14-B24 -> 2112 | C26: =C14-C24 -> 7094.28 | D26: =D14-D24 -> 17400.028 | E26: =E14-E24 -> 27594.949 | F26: =F14-F24 -> 37675.718
A27: Monthly FCF | B27: =B26/12 -> 176 | C27: =C26/12 -> 591.19 | D27: =D26/12 -> 1450.0024 | E27: =E26/12 -> 2299.5791 | F27: =F26/12 -> 3139.6431
A28: Savings Rate | B28: =B26/B14 -> 0.011354839 | C28: =C26/C14 -> 0.034271884 | D28: =D26/D14 -> 0.07873316 | E28: =E26/E14 -> 0.11742532 | F28: =F26/F14 -> 0.1513081
A30: BALANCE SHEET
A31: Beginning Liquid Assets | B31: =Assumptions!$B$48+Assumptions!$B$47 -> 380000 | C31: =B33 -> 382112 | D31: =C33 -> 389206.28 | E31: =D33 -> 406606.31 | F31: =E33 -> 434201.26
A32: + Free Cash Flow | B32: =B26 -> 2112 | C32: =C26 -> 7094.28 | D32: =D26 -> 17400.028 | E32: =E26 -> 27594.949 | F32: =F26 -> 37675.718
A33: Ending Liquid Assets | B33: =B31+B32 -> 382112 | C33: =C31+C32 -> 389206.28 | D33: =D31+D32 -> 406606.31 | E33: =E31+E32 -> 434201.26 | F33: =F31+F32 -> 471876.98
A35: Home Value (3% appreciation) | B35: =1180640*(1.03^0) -> 1180640 | C35: =1180640*(1.03^1) -> 1216059.2 | D35: =1180640*(1.03^2) -> 1252541 | E35: =1180640*(1.03^3) -> 1290117.2 | F35: =1180640*(1.03^4) -> 1328820.7
A36: Mortgage Balance | B36: =Assumptions!$B$50 -> 826448 | C36: =B36-(B36*Assumptions!$B$54/12*12-4692.48*12+B36*Assumptions!$B$54) -> 791848.48 | D36: =C36-(C36*Assumptions!$B$54/12*12-4692.48*12+C36*Assumptions!$B$54) -> 761054.91 | E36: =D36-(D36*Assumptions!$B$54/12*12-4692.48*12+D36*Assumptions!$B$54) -> 733648.63 | F36: =E36-(E36*Assumptions!$B$54/12*12-4692.48*12+E36*Assumptions!$B$54) -> 709257.04
A37: Home Equity | B37: =B35-B36 -> 354192 | C37: =C35-C36 -> 424210.72 | D37: =D35-D36 -> 491486.07 | E37: =E35-E36 -> 556468.58 | F37: =F35-F36 -> 619563.68
A39: TOTAL NET WORTH | B39: =B33+B37+Assumptions!$B$49 -> 886304 | C39: =C33+C37+Assumptions!$B$49 -> 963417 | D39: =D33+D37+Assumptions!$B$49 -> 1048092.4 | E39: =E33+E37+Assumptions!$B$49 -> 1140669.8 | F39: =F33+F37+Assumptions!$B$49 -> 1241440.7
A42: QUICK SCENARIOS
A43: Scenario | B43: 2030 Net Worth | C43: Notes
A44: Base Case (Current) | B44: =F39 -> 1241440.7 | C44: Model assumptions
A45: James Venture Fails | B45: =F39-SUM(F7,E7,D7,C7)*0.75 -> 1241440.7 | C45: No venture income
A46: Laura Hours Drop 20% | B46: =F39-(496000-496000*0.8)*5*0.7 -> 894240.66 | C46: Reduced billings

Sheet Budget vs Actual
A1: BUDGET VS ACTUAL
A2: =CONCATENATE("Period: ",TEXT(Config!B6,"MMM DD")," - ",TEXT(Config!B7,"MMM DD")) -> Period: Oct 30 - Jan 28
A4: CATEGORY BUDGETS
A5: Category | B5: Budget/Mo | C5: Actual/Mo | D5: Variance | E5: Status | F5: vs Prior
A6: Groceries | B6: =Config!B31 -> 2000 | C6: =ABS(SUMIFS('Raw Data'!G3:G10000,'Raw Data'!C3:C10000,A6,'Raw Data'!G3:G10000,"<0",'Raw Data'!A3:A10000,">="&Config!$B$6,'Raw Data'!A3:A10000,"<="&Config!$B$7,'Raw Data'!J3:J10000,"<>Business",'Raw Data'!J3:J10000,"<>Split-Parent"))/Config!$B$9 -> 1999.5867 | D6: =B6-C6 -> 0.41333333 | E6: =IF(D6<0,"⚠ OVER","✓ OK") -> ✓ OK | F6: =C6-(ABS(SUMIFS('Raw Data'!G3:G10000,'Raw Data'!C3:C10000,A6,'Raw Data'!G3:G10000,"<0",'Raw Data'!A3:A10000,">="&(Config!$B$6-(Config!$B$7-Config!$B$6)),'Raw Data'!A3:A10000,"<"&Config!$B$6,'Raw Data'!J3:J10000,"<>Business",'Raw Data'!J3:J10000,"<>Split-Parent"))/Config!$B$9) -> 1999.5867
A7: Restaurants & Bars | B7: =Config!B32 -> 800 | C7: =ABS(SUMIFS('Raw Data'!G3:G10000,'Raw Data'!C3:C10000,A7,'Raw Data'!G3:G10000,"<0",'Raw Data'!A3:A10000,">="&Config!$B$6,'Raw Data'!A3:A10000,"<="&Config!$B$7,'Raw Data'!J3:J10000,"<>Business",'Raw Data'!J3:J10000,"<>Split-Parent"))/Config!$B$9 -> 1057.7567 | D7: =B7-C7 -> -257.75667 | E7: =IF(D7<0,"⚠ OVER","✓ OK") -> ⚠ OVER | F7: =C7-(ABS(SUMIFS('Raw Data'!G3:G10000,'Raw Data'!C3:C10000,A7,'Raw Data'!G3:G10000,"<0",'Raw Data'!A3:A10000,">="&(Config!$B$6-(Config!$B$7-Config!$B$6)),'Raw Data'!A3:A10000,"<"&Config!$B$6,'Raw Data'!J3:J10000,"<>Business",'Raw Data'!J3:J10000,"<>Split-Parent"))/Config!$B$9) -> 1057.7567
A8: Shopping | B8: =Config!B33 -> 2500 | C8: =ABS(SUMIFS('Raw Data'!G3:G10000,'Raw Data'!C3:C10000,A8,'Raw Data'!G3:G10000,"<0",'Raw Data'!A3:A10000,">="&Config!$B$6,'Raw Data'!A3:A10000,"<="&Config!$B$7,'Raw Data'!J3:J10000,"<>Business",'Raw Data'!J3:J10000,"<>Split-Parent"))/Config!$B$9 -> 3382.5133 | D8: =B8-C8 -> -882.51333 | E8: =IF(D8<0,"⚠ OVER","✓ OK") -> ⚠ OVER | F8: =C8-(ABS(SUMIFS('Raw Data'!G3:G10000,'Raw Data'!C3:C10000,A8,'Raw Data'!G3:G10000,"<0",'Raw Data'!A3:A10000,">="&(Config!$B$6-(Config!$B$7-Config!$B$6)),'Raw Data'!A3:A10000,"<"&Config!$B$6,'Raw Data'!J3:J10000,"<>Business",'Raw Data'!J3:J10000,"<>Split-Parent"))/Config!$B$9) -> 3382.5133
A9: Gas | B9: =Config!B34 -> 500 | C9: =ABS(SUMIFS('Raw Data'!G3:G10000,'Raw Data'!C3:C10000,A9,'Raw Data'!G3:G10000,"<0",'Raw Data'!A3:A10000,">="&Config!$B$6,'Raw Data'!A3:A10000,"<="&Config!$B$7,'Raw Data'!J3:J10000,"<>Business",'Raw Data'!J3:J10000,"<>Split-Parent"))/Config!$B$9 -> 481.25 | D9: =B9-C9 -> 18.75 | E9: =IF(D9<0,"⚠ OVER","✓ OK") -> ✓ OK | F9: =C9-(ABS(SUMIFS('Raw Data'!G3:G10000,'Raw Data'!C3:C10000,A9,'Raw Data'!G3:G10000,"<0",'Raw Data'!A3:A10000,">="&(Config!$B$6-(Config!$B$7-Config!$B$6)),'Raw Data'!A3:A10000,"<"&Config!$B$6,'Raw Data'!J3:J10000,"<>Business",'Raw Data'!J3:J10000,"<>Split-Parent"))/Config!$B$9) -> 481.25
A10: Entertainment & Recreation | B10: =Config!B35 -> 450 | C10: =ABS(SUMIFS('Raw Data'!G3:G10000,'Raw Data'!C3:C10000,A10,'Raw Data'!G3:G10000,"<0",'Raw Data'!A3:A10000,">="&Config!$B$6,'Raw Data'!A3:A10000,"<="&Config!$B$7,'Raw Data'!J3:J10000,"<>Business",'Raw Data'!J3:J10000,"<>Split-Parent"))/Config!$B$9 -> 462.83 | D10: =B10-C10 -> -12.83 | E10: =IF(D10<0,"⚠ OVER","✓ OK") -> ⚠ OVER | F10: =C10-(ABS(SUMIFS('Raw Data'!G3:G10000,'Raw Data'!C3:C10000,A10,'Raw Data'!G3:G10000,"<0",'Raw Data'!A3:A10000,">="&(Config!$B$6-(Config!$B$7-Config!$B$6)),'Raw Data'!A3:A10000,"<"&Config!$B$6,'Raw Data'!J3:J10000,"<>Business",'Raw Data'!J3:J10000,"<>Split-Parent"))/Config!$B$9) -> 462.83
A11: Medical | B11: =Config!B36 -> 400 | C11: =ABS(SUMIFS('Raw Data'!G3:G10000,'Raw Data'!C3:C10000,A11,'Raw Data'!G3:G10000,"<0",'Raw Data'!A3:A10000,">="&Config!$B$6,'Raw Data'!A3:A10000,"<="&Config!$B$7,'Raw Data'!J3:J10000,"<>Business",'Raw Data'!J3:J10000,"<>Split-Parent"))/Config!$B$9 -> 579.76333 | D11: =B11-C11 -> -179.76333 | E11: =IF(D11<0,"⚠ OVER","✓ OK") -> ⚠ OVER | F11: =C11-(ABS(SUMIFS('Raw Data'!G3:G10000,'Raw Data'!C3:C10000,A11,'Raw Data'!G3:G10000,"<0",'Raw Data'!A3:A10000,">="&(Config!$B$6-(Config!$B$7-Config!$B$6)),'Raw Data'!A3:A10000,"<"&Config!$B$6,'Raw Data'!J3:J10000,"<>Business",'Raw Data'!J3:J10000,"<>Split-Parent"))/Config!$B$9) -> 579.76333
A12: Personal | B12: =Config!B37 -> 300 | C12: =ABS(SUMIFS('Raw Data'!G3:G10000,'Raw Data'!C3:C10000,A12,'Raw Data'!G3:G10000,"<0",'Raw Data'!A3:A10000,">="&Config!$B$6,'Raw Data'!A3:A10000,"<="&Config!$B$7,'Raw Data'!J3:J10000,"<>Business",'Raw Data'!J3:J10000,"<>Split-Parent"))/Config!$B$9 -> 263.59333 | D12: =B12-C12 -> 36.406667 | E12: =IF(D12<0,"⚠ OVER","✓ OK") -> ✓ OK | F12: =C12-(ABS(SUMIFS('Raw Data'!G3:G10000,'Raw Data'!C3:C10000,A12,'Raw Data'!G3:G10000,"<0",'Raw Data'!A3:A10000,">="&(Config!$B$6-(Config!$B$7-Config!$B$6)),'Raw Data'!A3:A10000,"<"&Config!$B$6,'Raw Data'!J3:J10000,"<>Business",'Raw Data'!J3:J10000,"<>Split-Parent"))/Config!$B$9) -> 263.59333
A13: Clothing | B13: =Config!B38 -> 500 | C13: =ABS(SUMIFS('Raw Data'!G3:G10000,'Raw Data'!C3:C10000,A13,'Raw Data'!G3:G10000,"<0",'Raw Data'!A3:A10000,">="&Config!$B$6,'Raw Data'!A3:A10000,"<="&Config!$B$7,'Raw Data'!J3:J10000,"<>Business",'Raw Data'!J3:J10000,"<>Split-Parent"))/Config!$B$9 -> 595 | D13: =B13-C13 -> -95 | E13: =IF(D13<0,"⚠ OVER","✓ OK") -> ⚠ OVER | F13: =C13-(ABS(SUMIFS('Raw Data'!G3:G10000,'Raw Data'!C3:C10000,A13,'Raw Data'!G3:G10000,"<0",'Raw Data'!A3:A10000,">="&(Config!$B$6-(Config!$B$7-Config!$B$6)),'Raw Data'!A3:A10000,"<"&Config!$B$6,'Raw Data'!J3:J10000,"<>Business",'Raw Data'!J3:J10000,"<>Split-Parent"))/Config!$B$9) -> 595
A14: Home Improvement | B14: =Config!B39 -> 500 | C14: =ABS(SUMIFS('Raw Data'!G3:G10000,'Raw Data'!C3:C10000,A14,'Raw Data'!G3:G10000,"<0",'Raw Data'!A3:A10000,">="&Config!$B$6,'Raw Data'!A3:A10000,"<="&Config!$B$7,'Raw Data'!J3:J10000,"<>Business",'Raw Data'!J3:J10000,"<>Split-Parent"))/Config!$B$9 -> 8630.7033 | D14: =B14-C14 -> -8130.7033 | E14: =IF(D14<0,"⚠ OVER","✓ OK") -> ⚠ OVER | F14: =C14-(ABS(SUMIFS('Raw Data'!G3:G10000,'Raw Data'!C3:C10000,A14,'Raw Data'!G3:G10000,"<0",'Raw Data'!A3:A10000,">="&(Config!$B$6-(Config!$B$7-Config!$B$6)),'Raw Data'!A3:A10000,"<"&Config!$B$6,'Raw Data'!J3:J10000,"<>Business",'Raw Data'!J3:J10000,"<>Split-Parent"))/Config!$B$9) -> 8630.7033
A15: Education | B15: =Config!B40 -> 500 | C15: =ABS(SUMIFS('Raw Data'!G3:G10000,'Raw Data'!C3:C10000,A15,'Raw Data'!G3:G10000,"<0",'Raw Data'!A3:A10000,">="&Config!$B$6,'Raw Data'!A3:A10000,"<="&Config!$B$7,'Raw Data'!J3:J10000,"<>Business",'Raw Data'!J3:J10000,"<>Split-Parent"))/Config!$B$9 -> 494 | D15: =B15-C15 -> 6 | E15: =IF(D15<0,"⚠ OVER","✓ OK") -> ✓ OK | F15: =C15-(ABS(SUMIFS('Raw Data'!G3:G10000,'Raw Data'!C3:C10000,A15,'Raw Data'!G3:G10000,"<0",'Raw Data'!A3:A10000,">="&(Config!$B$6-(Config!$B$7-Config!$B$6)),'Raw Data'!A3:A10000,"<"&Config!$B$6,'Raw Data'!J3:J10000,"<>Business",'Raw Data'!J3:J10000,"<>Split-Parent"))/Config!$B$9) -> 494
A16: Fitness | B16: =Config!B41 -> 175 | C16: =ABS(SUMIFS('Raw Data'!G3:G10000,'Raw Data'!C3:C10000,A16,'Raw Data'!G3:G10000,"<0",'Raw Data'!A3:A10000,">="&Config!$B$6,'Raw Data'!A3:A10000,"<="&Config!$B$7,'Raw Data'!J3:J10000,"<>Business",'Raw Data'!J3:J10000,"<>Split-Parent"))/Config!$B$9 -> 173.02 | D16: =B16-C16 -> 1.98 | E16: =IF(D16<0,"⚠ OVER","✓ OK") -> ✓ OK | F16: =C16-(ABS(SUMIFS('Raw Data'!G3:G10000,'Raw Data'!C3:C10000,A16,'Raw Data'!G3:G10000,"<0",'Raw Data'!A3:A10000,">="&(Config!$B$6-(Config!$B$7-Config!$B$6)),'Raw Data'!A3:A10000,"<"&Config!$B$6,'Raw Data'!J3:J10000,"<>Business",'Raw Data'!J3:J10000,"<>Split-Parent"))/Config!$B$9) -> 173.02
A17: Child Care | B17: =Config!B42 -> 250 | C17: =ABS(SUMIFS('Raw Data'!G3:G10000,'Raw Data'!C3:C10000,A17,'Raw Data'!G3:G10000,"<0",'Raw Data'!A3:A10000,">="&Config!$B$6,'Raw Data'!A3:A10000,"<="&Config!$B$7,'Raw Data'!J3:J10000,"<>Business",'Raw Data'!J3:J10000,"<>Split-Parent"))/Config!$B$9 -> 78.186667 | D17: =B17-C17 -> 171.81333 | E17: =IF(D17<0,"⚠ OVER","✓ OK") -> ✓ OK | F17: =C17-(ABS(SUMIFS('Raw Data'!G3:G10000,'Raw Data'!C3:C10000,A17,'Raw Data'!G3:G10000,"<0",'Raw Data'!A3:A10000,">="&(Config!$B$6-(Config!$B$7-Config!$B$6)),'Raw Data'!A3:A10000,"<"&Config!$B$6,'Raw Data'!J3:J10000,"<>Business",'Raw Data'!J3:J10000,"<>Split-Parent"))/Config!$B$9) -> 78.186667
A18: Coffee Shops | B18: =Config!B43 -> 100 | C18: =ABS(SUMIFS('Raw Data'!G3:G10000,'Raw Data'!C3:C10000,A18,'Raw Data'!G3:G10000,"<0",'Raw Data'!A3:A10000,">="&Config!$B$6,'Raw Data'!A3:A10000,"<="&Config!$B$7,'Raw Data'!J3:J10000,"<>Business",'Raw Data'!J3:J10000,"<>Split-Parent"))/Config!$B$9 -> 7.2866667 | D18: =B18-C18 -> 92.713333 | E18: =IF(D18<0,"⚠ OVER","✓ OK") -> ✓ OK | F18: =C18-(ABS(SUMIFS('Raw Data'!G3:G10000,'Raw Data'!C3:C10000,A18,'Raw Data'!G3:G10000,"<0",'Raw Data'!A3:A10000,">="&(Config!$B$6-(Config!$B$7-Config!$B$6)),'Raw Data'!A3:A10000,"<"&Config!$B$6,'Raw Data'!J3:J10000,"<>Business",'Raw Data'!J3:J10000,"<>Split-Parent"))/Config!$B$9) -> 7.2866667
A19: Parking & Tolls | B19: =Config!B44 -> 150 | C19: =ABS(SUMIFS('Raw Data'!G3:G10000,'Raw Data'!C3:C10000,A19,'Raw Data'!G3:G10000,"<0",'Raw Data'!A3:A10000,">="&Config!$B$6,'Raw Data'!A3:A10000,"<="&Config!$B$7,'Raw Data'!J3:J10000,"<>Business",'Raw Data'!J3:J10000,"<>Split-Parent"))/Config!$B$9 -> 135.45 | D19: =B19-C19 -> 14.55 | E19: =IF(D19<0,"⚠ OVER","✓ OK") -> ✓ OK | F19: =C19-(ABS(SUMIFS('Raw Data'!G3:G10000,'Raw Data'!C3:C10000,A19,'Raw Data'!G3:G10000,"<0",'Raw Data'!A3:A10000,">="&(Config!$B$6-(Config!$B$7-Config!$B$6)),'Raw Data'!A3:A10000,"<"&Config!$B$6,'Raw Data'!J3:J10000,"<>Business",'Raw Data'!J3:J10000,"<>Split-Parent"))/Config!$B$9) -> 135.45
A22: MERCHANT BUDGETS
A23: Category | B23: Budget/Mo | C23: Actual/Mo | D23: Variance | E23: Status | F23: vs Prior
A24: Amazon | B24: =Config!E31 -> 1000 | C24: =ABS(SUMIFS('Raw Data'!G3:G10000,'Raw Data'!B3:B10000,"*"&A24&"*",'Raw Data'!G3:G10000,"<0",'Raw Data'!A3:A10000,">="&Config!$B$6,'Raw Data'!A3:A10000,"<="&Config!$B$7,'Raw Data'!J3:J10000,"<>Business",'Raw Data'!J3:J10000,"<>Split-Parent"))/Config!$B$9 -> 1404.5367 | D24: =B24-C24 -> -404.53667 | E24: =IF(D24<0,"⚠ OVER","✓ OK") -> ⚠ OVER | F24: =C24-(ABS(SUMIFS('Raw Data'!G3:G10000,'Raw Data'!B3:B10000,"*"&A24&"*",'Raw Data'!G3:G10000,"<0",'Raw Data'!A3:A10000,">="&(Config!$B$6-(Config!$B$7-Config!$B$6)),'Raw Data'!A3:A10000,"<"&Config!$B$6,'Raw Data'!J3:J10000,"<>Business",'Raw Data'!J3:J10000,"<>Split-Parent"))/Config!$B$9) -> 1404.5367
A25: Uber Eats | B25: =Config!E32 -> 300 | C25: =ABS(SUMIFS('Raw Data'!G3:G10000,'Raw Data'!B3:B10000,"*"&A25&"*",'Raw Data'!G3:G10000,"<0",'Raw Data'!A3:A10000,">="&Config!$B$6,'Raw Data'!A3:A10000,"<="&Config!$B$7,'Raw Data'!J3:J10000,"<>Business",'Raw Data'!J3:J10000,"<>Split-Parent"))/Config!$B$9 -> 459.78333 | D25: =B25-C25 -> -159.78333 | E25: =IF(D25<0,"⚠ OVER","✓ OK") -> ⚠ OVER | F25: =C25-(ABS(SUMIFS('Raw Data'!G3:G10000,'Raw Data'!B3:B10000,"*"&A25&"*",'Raw Data'!G3:G10000,"<0",'Raw Data'!A3:A10000,">="&(Config!$B$6-(Config!$B$7-Config!$B$6)),'Raw Data'!A3:A10000,"<"&Config!$B$6,'Raw Data'!J3:J10000,"<>Business",'Raw Data'!J3:J10000,"<>Split-Parent"))/Config!$B$9) -> 459.78333
A26: Target | B26: =Config!E33 -> 400 | C26: =ABS(SUMIFS('Raw Data'!G3:G10000,'Raw Data'!B3:B10000,"*"&A26&"*",'Raw Data'!G3:G10000,"<0",'Raw Data'!A3:A10000,">="&Config!$B$6,'Raw Data'!A3:A10000,"<="&Config!$B$7,'Raw Data'!J3:J10000,"<>Business",'Raw Data'!J3:J10000,"<>Split-Parent"))/Config!$B$9 -> 744.82333 | D26: =B26-C26 -> -344.82333 | E26: =IF(D26<0,"⚠ OVER","✓ OK") -> ⚠ OVER | F26: =C26-(ABS(SUMIFS('Raw Data'!G3:G10000,'Raw Data'!B3:B10000,"*"&A26&"*",'Raw Data'!G3:G10000,"<0",'Raw Data'!A3:A10000,">="&(Config!$B$6-(Config!$B$7-Config!$B$6)),'Raw Data'!A3:A10000,"<"&Config!$B$6,'Raw Data'!J3:J10000,"<>Business",'Raw Data'!J3:J10000,"<>Split-Parent"))/Config!$B$9) -> 744.82333
A27: Publix | B27: =Config!E34 -> 1200 | C27: =ABS(SUMIFS('Raw Data'!G3:G10000,'Raw Data'!B3:B10000,"*"&A27&"*",'Raw Data'!G3:G10000,"<0",'Raw Data'!A3:A10000,">="&Config!$B$6,'Raw Data'!A3:A10000,"<="&Config!$B$7,'Raw Data'!J3:J10000,"<>Business",'Raw Data'!J3:J10000,"<>Split-Parent"))/Config!$B$9 -> 1150.24 | D27: =B27-C27 -> 49.76 | E27: =IF(D27<0,"⚠ OVER","✓ OK") -> ✓ OK | F27: =C27-(ABS(SUMIFS('Raw Data'!G3:G10000,'Raw Data'!B3:B10000,"*"&A27&"*",'Raw Data'!G3:G10000,"<0",'Raw Data'!A3:A10000,">="&(Config!$B$6-(Config!$B$7-Config!$B$6)),'Raw Data'!A3:A10000,"<"&Config!$B$6,'Raw Data'!J3:J10000,"<>Business",'Raw Data'!J3:J10000,"<>Split-Parent"))/Config!$B$9) -> 1150.24
A30: MERCHANT DEEP-DIVES
A31: Amazon | B31: Transactions: | C31: =COUNTIFS('Raw Data'!B3:B10000,"*Amazon*",'Raw Data'!G3:G10000,"<0",'Raw Data'!A3:A10000,">="&Config!B6,'Raw Data'!A3:A10000,"<="&Config!B7,'Raw Data'!J3:J10000,"") -> 123 | D31: Avg/order: | E31: =ABS(SUMIFS('Raw Data'!G3:G10000,'Raw Data'!B3:B10000,"*Amazon*",'Raw Data'!G3:G10000,"<0",'Raw Data'!A3:A10000,">="&Config!B6,'Raw Data'!A3:A10000,"<="&Config!B7,'Raw Data'!J3:J10000,""))/MAX(1,C31) -> 34.256992
A33: Grocery Stores
A34: Publix | B34: =ABS(SUMIFS('Raw Data'!G3:G10000,'Raw Data'!B3:B10000,"*Publix*",'Raw Data'!C3:C10000,"Groceries",'Raw Data'!G3:G10000,"<0",'Raw Data'!A3:A10000,">="&Config!B6,'Raw Data'!A3:A10000,"<="&Config!B7,'Raw Data'!J3:J10000,"")) -> 3418.7
A35: Kroger | B35: =ABS(SUMIFS('Raw Data'!G3:G10000,'Raw Data'!B3:B10000,"*Kroger*",'Raw Data'!C3:C10000,"Groceries",'Raw Data'!G3:G10000,"<0",'Raw Data'!A3:A10000,">="&Config!B6,'Raw Data'!A3:A10000,"<="&Config!B7,'Raw Data'!J3:J10000,"")) -> 1199.12
A36: Sprouts | B36: =ABS(SUMIFS('Raw Data'!G3:G10000,'Raw Data'!B3:B10000,"*Sprouts*",'Raw Data'!C3:C10000,"Groceries",'Raw Data'!G3:G10000,"<0",'Raw Data'!A3:A10000,">="&Config!B6,'Raw Data'!A3:A10000,"<="&Config!B7,'Raw Data'!J3:J10000,"")) -> 368.08
A37: Costco | B37: =ABS(SUMIFS('Raw Data'!G3:G10000,'Raw Data'!B3:B10000,"*Costco*",'Raw Data'!C3:C10000,"Groceries",'Raw Data'!G3:G10000,"<0",'Raw Data'!A3:A10000,">="&Config!B6,'Raw Data'!A3:A10000,"<="&Config!B7,'Raw Data'!J3:J10000,"")) -> 0

Sheet Balance Sheet
A1: 📊 STICE FAMILY BALANCE SHEET
A2: As of January 29, 2026 - Blue cells are inputs to update
A4: ASSETS
A5: Real Estate
A6: 761 E Morningside Dr NE (New Home) | B6: 1180640 | C6: Purchase price 1/29/26
A7: 980 Rawlins St SE (Current Home - Selling April) | B7: 650000 | C7: Est. market value
A8: Total Real Estate | B8: =SUM(B6:B7) -> 1830640
A10: Investment Accounts
A11: Schwab Brokerage | B11: 1000 | C11: Estimate - update with actual
A12: Robinhood | B12: 25000 | C12: Estimate
A13: Retirement Accounts (401k/IRA) | B13: 25000 | C13: Estimate
A14: Total Investments | B14: =SUM(B11:B13) -> 51000
A16: Cash & Bank Accounts
A17: Wells Fargo Checking (...2051) | B17: 90000 | C17: Estimate
A18: Wells Fargo Savings (...8781) | B18: 5000 | C18: Estimate
A19: Schwab Checking (...915) | B19: 1000 | C19: Estimate
A20: Total Cash | B20: =SUM(B17:B19) -> 96000
A22: TOTAL ASSETS | B22: =B8+B14+B20 -> 1977640
A24: LIABILITIES
A25: Mortgages
A26: Morningside Home (UWM) | B26: 826448 | C26: 5.5%, 30yr, $4,692.48 P&I
A27: Rawlins Home (Mr. Cooper) | B27: 300000 | C27: Estimate - paying off in April
A28: Total Mortgages | B28: =SUM(B26:B27) -> 1126448
A30: Other Debt
A31: Student Loans (Aidvantage) | B31: 75000 | C31: Estimate - $1,024/mo payment
A32: Auto Loan | B32: 25000 | C32: Estimate - $680/mo payment
A33: Credit Cards | B33: 0 | C33: Paid in full monthly
A34: Total Other Debt | B34: =SUM(B31:B33) -> 100000
A36: TOTAL LIABILITIES | B36: =B28+B34 -> 1226448
A38: NET WORTH | B38: =B22-B36 -> 751192

Sheet Config
A1: CONFIGURATION & SETTINGS
A3: 📅 ANALYSIS PERIOD
A4: These dates control what period all reports analyze. Adjust as needed.
A6: Analysis Start Date: | B6: 45960
A7: Analysis End Date: | B7: 46050
A8: Days in Period: | B8: =B7-B6 -> 90
A9: Months in Period: | B9: =ROUND((B7-B6)/30.44,1) -> 3
A11: QUICK PERIOD PRESETS (copy formulas to B6/B7):
A12: Period | B12: Start Formula | C12: End Formula
A13: Last 30 days | B13: =TODAY()-30 -> 46031 | C13: =TODAY() -> 46061
A14: Last 60 days | B14: =TODAY()-60 -> 46001 | C14: =TODAY() -> 46061
A15: Last 90 days | B15: =TODAY()-90 -> 45971 | C15: =TODAY() -> 46061
A16: This month | B16: =DATE(YEAR(TODAY()),MONTH(TODAY()),1) -> 46054 | C16: =TODAY() -> 46061
A17: Last month | B17: =DATE(YEAR(TODAY()),MONTH(TODAY())-1,1) -> 46023 | C17: =DATE(YEAR(TODAY()),MONTH(TODAY()),0) -> 46053
A18: Year to date | B18: =DATE(YEAR(TODAY()),1,1) -> 46023 | C18: =TODAY() -> 46061
A19: All data | B19: =MIN('Raw Data'!A:A) -> 45960 | C19: =MAX('Raw Data'!A:A) -> 46050
A22: 📊 DATA STATISTICS
A23: Total rows in Raw Data: | B23: =COUNTA('Raw Data'!A3:A10000) -> 791
A24: Earliest transaction: | B24: =MIN('Raw Data'!A3:A10000) -> 45960
A25: Latest transaction: | B25: =MAX('Raw Data'!A3:A10000) -> 46050
A26: Rows in analysis period: | B26: =COUNTIFS('Raw Data'!A3:A10000,">="&B6,'Raw Data'!A3:A10000,"<="&B7,'Raw Data'!J3:J10000,"<>Business",'Raw Data'!J3:J10000,"<>Split-Parent") -> 791
A29: 💰 MONTHLY BUDGET TARGETS | D29: 🏪 MERCHANT BUDGETS
A30: Category | B30: Monthly Budget | D30: Merchant Contains | E30: Monthly Budget
A31: Groceries | B31: 2000 | D31: Amazon | E31: 1000
A32: Restaurants & Bars | B32: 800 | D32: Uber Eats | E32: 300
A33: Shopping | B33: 2500 | D33: Target | E33: 400
A34: Gas | B34: 500 | D34: Publix | E34: 1200
A35: Entertainment & Recreation | B35: 450
A36: Medical | B36: 400
A37: Personal | B37: 300
A38: Clothing | B38: 500
A39: Home Improvement | B39: 500
A40: Education | B40: 500
A41: Fitness | B41: 175
A42: Child Care | B42: 250
A43: Coffee Shops | B43: 100
A44: Parking & Tolls | B44: 150
A48: Target Savings Rate: | B48: 0.2 | D48: 🏠 NEW MORTGAGE (Morningside)
D49: Monthly P&I: | E49: 4692.48
A50: 📊 EXCLUDED TRANSACTIONS | D50: Monthly Taxes/Ins/HOA: | E50: 1827.07
...

Sheet Raw Data
A1: MASTER TRANSACTION DATA - Type column: blank=Personal (included), "Business"=excluded, "Split-Parent"=excluded (see split rows)
A2: Date | B2: Merchant | C2: Category | D2: Account | E2: Original Statement | F2: Notes | G2: Amount | H2: Tags | I2: Owner | J2: Type | K2: Split From Row
A3: 46050 | B3: Target | C3: Shopping | D3: EVERYDAY CHECKING (...2051) | E3: RECURRING PAYMENT AUTHORIZED ON 01/27 TARGET.COM WWW.TARGET.CO MN S586027475145667 CARD 6865 | G3: -10.99 | I3: Laura Holland Stice
A4: 46050 | B4: Publix | C4: Groceries | D4: Delta SkyMiles® Reserve Card (...1009) | E4: PUBLIX | G4: -49.33 | I4: Jimmy Stice
A5: 46049 | B5: Amazon | C5: Shopping | D5: Schwab Investor Card (...1004) | E5: AMAZON MARKETPLACE NAMZN.COM/BILL WA | G5: -83.79 | I5: Jimmy Stice
A6: 46049 | B6: Amazon | C6: Shopping | D6: Schwab Investor Card (...1004) | E6: AMAZON DIGIT*6U7XG25888-802-3080 WA | G6: -10.99 | I6: Jimmy Stice
A7: 46049 | B7: Prime Video | C7: Entertainment & Recreation | D7: Delta SkyMiles® Reserve Card (...1007) | E7: PRIME VIDEO CHANNELSAMZN.COM/BILL WA | G7: -7.99 | I7: Laura Holland Stice
A8: 46049 | B8: Amazon | C8: Shopping | D8: Delta SkyMiles® Reserve Card (...1007) | E8: AMAZON MARKEPLACE NA PA | G8: -32.33 | I8: Laura Holland Stice
A9: 46049 | B9: Experian | C9: Financial Fees | D9: EVERYDAY CHECKING (...2051) | E9: RECURRING PAYMENT AUTHORIZED ON 01/26 Experian* Credit R 479-3436237 CA S466026377287718 CARD 6865 | G9: -24.99 | I9: Laura Holland Stice
A10: 46049 | B10: CVS | C10: Medical | D10: EVERYDAY CHECKING (...2051) | E10: PURCHASE AUTHORIZED ON 01/27 CVS/PHARMACY #07 07336--5 ATLANTA GA P386027521582936 CARD 6865 | G10: -17.5 | I10: Laura Holland Stice
A11: 46049 | B11: AT&T | C11: Phone | D11: EVERYDAY CHECKING (...2051) | E11: ATT PAYMENT 012526 474125001EPAYI LAURA HOLLAND SCLAFANI | G11: -95 | I11: Laura Holland Stice
A12: 46049 | B12: JP Morgan Chase | C12: Transfer | D12: EVERYDAY CHECKING (...2051) | E12: JPMorgan Chase Ext Trnsfr 260127 27393484711 LAURA HOLLAND SCLAFANI | G12: -340.3 | I12: Laura Holland Stice
A13: 46049 | B13: Rhino | C13: Auto Maintenance | D13: Delta SkyMiles® Reserve Card (...1009) | E13: RHINO AIR GA | G13: -3.2 | I13: Jimmy Stice
A14: 46049 | B14: Kroger | C14: Groceries | D14: Delta SkyMiles® Reserve Card (...1009) | E14: KROGER | G14: -104.05 | I14: Jimmy Stice
... A142: 46034 | B142: Amazon | C142: Shopping | D142: Schwab Investor Card (...1004) | E142: AMAZON MARKETPLACE NAMZN.COM/BILL WA | G142: -57.49 | I142: Jimmy Stice
A143: 46034 | B143: Publix | C143: Coffee Shops | D143: Delta SkyMiles® Reserve Card (...1009) | E143: PUBLIX #1825 0000018ATLANTA GA | F143: 1 x STARBUCKS 40 OZ - $6.99 1 x STOK ESPRSSO 48OZ - $6.49 | G143: -14.17 | H143: Receipt Import | I143: Jimmy Stice
A144: 46034 | B144: Publix | C144: Restaurants & Bars | D144: Delta SkyMiles® Reserve Card (...1009) | E144: PUBLIX #1825 0000018ATLANTA GA | F144: 1 x GW CHICKEN TENDER - $7.99 | G144: -8.4 | H144: Receipt Import | I144: Jimmy Stice
A145: 46034 | B145: Publix | C145: Medical | D145: Delta SkyMiles® Reserve Card (...1009) | E145: PUBLIX #1825 0000018ATLANTA GA | F145: 1 x PUB ANTACID - $3.99 | G145: -4.19 | H145: Receipt Import | I145: Jimmy Stice
A146: 46034 | B146: Publix | C146: Groceries | D146: Delta SkyMiles® Reserve Card (...1009) | E146: PUBLIX #1825 0000018ATLANTA GA | F146: 1 x CUCUMBERS - $0.99 1 x WTRMLN CHKS SDLS - $4.63 1 x LACROIX ORANGE - $6.59 1 x JUST BARE L/BRD BT - $13.99 1 x LACROIX ORANGE - $6.59 1 x CALIFIA FARMS C/B - $5.99 1 x HERSHEY'S SYRUP - $9.99 1 x CHOB LOW SUGAR 4PK - $5.49 1 x EX-LAX R/S CHOC - $10.49 1 x EB EGGS HARD COOKE - $3.99 1 x STONY PLAIN WHOLE - $5.25 1 x MAYFIELD I/C SDWCH - $5.49 1 x HZ TOMATO KETCHUP - $8.49 1 x EB EGGS HARD COOKE - $3.99 1 x HAPPY EGG ORG 12CT - $6.99 1 x THMS WHEAT ENG MUF - $2.74 1 x BYF SPRING MIX - $3.99 1 x SABRA HUM FAM CLSC - $6.99 1 x ONIONS RED - $1.67 | G146: -120.21 | H146: Receipt Import | I146: Jimmy Stice
A147: 46034 | B147: Publix | C147: Charity | D147: Delta SkyMiles® Reserve Card (...1009) | E147: PUBLIX #1825 0000018ATLANTA GA | F147: 1 x SPECIAL OLYMPICS - $5.00 | G147: -5.26 | H147: Receipt Import | I147: Jimmy Stice
A148: 46034 | B148: Amazon | C148: Miscellaneous | D148: Delta SkyMiles® Reserve Card (...1009) | E148: AMAZON PRIME*843CJ0BAMZN.COM/BILL WA | G148: -2.99 | I148: Jimmy Stice
A149: 46034 | B149: Nuuly | C149: Clothing | D149: Delta SkyMiles® Reserve Card (...1007) | E149: NUULY PHILADELPHIA PA | G149: -29.4 | I149: Laura Holland Stice
A150: 46034 | B150: Nuuly | C150: Clothing | D150: Delta SkyMiles® Reserve Card (...1007) | E150: NUULY PHILADELPHIA PA | G150: -16.99 | I150: Laura Holland Stice
A151: 46034 | B151: Canva | C151: Shopping | D151: Delta SkyMiles® Reserve Card (...1007) | E151: CANVA* I04759-508427CAMDEN DE | G151: -15 | I151: Laura Holland Stice
A152: 46034 | B152: OpenAI | C152: Electronics | D152: Investor Checking ...915 (...915) | E152: OPENAI *CHATGPT SUBSCR OPENAI.COM | G152: -20 | I152: Jimmy Stice
A153: 46034 | B153: Venmo | C153: Transfer | D153: EVERYDAY CHECKING (...2051) | E153: VENMO PAYMENT 260111 1047542711899 LAURA HOLLAND | G153: -36 | I153: Laura Holland Stice
A154: 46034 | B154: Bp Am Pm | C154: Uncategorized | D154: EVERYDAY CHECKING (...2051) | E154: PURCHASE AUTHORIZED ON 01/10 BP#8983496AM/PM ATLANTA GA P000000953185188 CARD 6865 | G154: -3.58 | I154: Laura Holland Stice
A155: 46034 | B155: Babylist Checkout | C155: Shopping | D155: EVERYDAY CHECKING (...2051) | E155: PURCHASE AUTHORIZED ON 01/10 SP BABYLIST CHECKOUT.BABY CA S306010568050355 CARD 6865 | G155: -55.03 | I155: Laura Holland Stice
A156: 46034 | B156: Recurring Payment Skylight Frame Manage | C156: Uncategorized | D156: EVERYDAY CHECKING (...2051) | E156: RECURRING PAYMENT AUTHORIZED ON 01/10 SP SKYLIGHT FRAME US.MANAGE.MYS CA S466010474608549 CARD 6865 | G156: -325.59 | I156: Laura Holland Stice
A157: 46034 | B157: Venmo | C157: Transfer | D157: EVERYDAY CHECKING (...2051) | E157: VENMO CASHOUT 260112 1047565356048 LAURA HOLLAND | G157: 562.5 | I157: Laura Holland Stice
A158: 46033 | B158: Publix | C158: Groceries | D158: Delta SkyMiles® Reserve Card (...1009) | E158: PUBLIX #1825 0000018ATLANTA GA | G158: -32.18 | I158: Jimmy Stice
A159: 46033 | B159: Amazon | C159: Shopping | D159: Delta SkyMiles® Reserve Card (...1007) | E159: AMAZON.COM AMZN.COM/BILL WA | G159: -21.73 | I159: Laura Holland Stice
... A793: 45960 | B793: Parker New York | C793: Shopping | D793: Delta SkyMiles® Reserve Card (...1009) | E793: AplPay WARBY PARKER NEW YORK CITY NY | G793: -145 | I793: Jimmy Stice

Sheet Import
A1: 📥 DATA IMPORT CENTER
A3: STEP 1: Export transactions from Monarch (CSV or copy from web)
A4: STEP 2: Paste into the YELLOW area below (starting row 15)
A5: STEP 3: Check the Import Summary (shows duplicates & date range)
A6: STEP 4: If looks good, Copy rows from below → Paste into "Raw Data" sheet (append to bottom)
A7: STEP 5: Delete the data from this sheet (keep headers)
A8: Column J (Type): Leave blank for personal, enter "Business" for pass-through transactions
A9: ⚠️ DUPLICATE HANDLING: Column K flags potential duplicates already in Raw Data.
A10: Review flagged rows before copying. Delete dupes from here, not Raw Data.
A11: IMPORT SUMMARY (Auto-calculated)
A12: Rows in staging: | B12: =COUNTA(A16:A10000) -> 0 | C12: Date range: | D12: =IF(B12>0,TEXT(MIN(A16:A10000),"MM/DD")&" - "&TEXT(MAX(A16:A10000),"MM/DD"),"No data") -> No data | E12: Potential duplicates: | F12: =COUNTIF(K16:K10000,"⚠️ DUPLICATE") -> 0
A14: ⬇️ PASTE MONARCH EXPORT BELOW THIS ROW ⬇️
A15: Date | B15: Merchant | C15: Category | D15: Account | E15: Original Statement | F15: Notes | G15: Amount | H15: Tags | I15: Owner | J15: Type | K15: Dupe Check
K16: =IF(A16="","",IF(COUNTIFS('Raw Data'!A:A,A16,'Raw Data'!G:G,G16,'Raw Data'!B:B,B16)>0,"⚠️ DUPLICATE","✓ New"))
K17: =IF(A17="","",IF(COUNTIFS('Raw Data'!A:A,A17,'Raw Data'!G:G,G17,'Raw Data'!B:B,B17)>0,"⚠️ DUPLICATE","✓ New"))
K18: =IF(A18="","",IF(COUNTIFS('Raw Data'!A:A,A18,'Raw Data'!G:G,G18,'Raw Data'!B:B,B18)>0,"⚠️ DUPLICATE","✓ New"))
K19: =IF(A19="","",IF(COUNTIFS('Raw Data'!A:A,A19,'Raw Data'!G:G,G19,'Raw Data'!B:B,B19)>0,"⚠️ DUPLICATE","✓ New"))
K20: =IF(A20="","",IF(COUNTIFS('Raw Data'!A:A,A20,'Raw Data'!G:G,G20,'Raw Data'!B:B,B20)>0,"⚠️ DUPLICATE","✓ New"))
K21: =IF(A21="","",IF(COUNTIFS('Raw Data'!A:A,A21,'Raw Data'!G:G,G21,'Raw Data'!B:B,B21)>0,"⚠️ DUPLICATE","✓ New"))
K22: =IF(A22="","",IF(COUNTIFS('Raw Data'!A:A,A22,'Raw Data'!G:G,G22,'Raw Data'!B:B,B22)>0,"⚠️ DUPLICATE","✓ New"))
K23: =IF(A23="","",IF(COUNTIFS('Raw Data'!A:A,A23,'Raw Data'!G:G,G23,'Raw Data'!B:B,B23)>0,"⚠️ DUPLICATE","✓ New"))
K24: =IF(A24="","",IF(COUNTIFS('Raw Data'!A:A,A24,'Raw Data'!G:G,G24,'Raw Data'!B:B,B24)>0,"⚠️ DUPLICATE","✓ New"))
K25: =IF(A25="","",IF(COUNTIFS('Raw Data'!A:A,A25,'Raw Data'!G:G,G25,'Raw Data'!B:B,B25)>0,"⚠️ DUPLICATE","✓ New"))
K26: =IF(A26="","",IF(COUNTIFS('Raw Data'!A:A,A26,'Raw Data'!G:G,G26,'Raw Data'!B:B,B26)>0,"⚠️ DUPLICATE","✓ New"))
K27: =IF(A27="","",IF(COUNTIFS('Raw Data'!A:A,A27,'Raw Data'!G:G,G27,'Raw Data'!B:B,B27)>0,"⚠️ DUPLICATE","✓ New"))
... K50: =IF(A50="","",IF(COUNTIFS('Raw Data'!A:A,A50,'Raw Data'!G:G,G50,'Raw Data'!B:B,B50)>0,"⚠️ DUPLICATE","✓ New"))

Sheet Tools
A1: 🛠️ UTILITY TOOLS
A3: TRANSACTION SPLIT HELPER
A5: Enter Raw Data row #:
A7: Original Transaction:
A8: Date: | B8: {=IF(B5="","",INDEX('Raw Data'!A:A,B5))}
A9: Merchant: | B9: {=IF(B5="","",INDEX('Raw Data'!B:B,B5))}
A10: Amount: | B10: {=IF(B5="","",INDEX('Raw Data'!G:G,B5))}
A11: Account: | B11: {=IF(B5="","",INDEX('Raw Data'!D:D,B5))}
A13: Split Rows (copy to Raw Data when done):
A14: Date | B14: Merchant | C14: Category | D14: Account | E14: Notes | F14: Amount | G14: Owner
A15: =$B$8 | B15: =$B$9 | D15: =$B$11 | E15: SPLIT:
A16: =$B$8 | B16: =$B$9 | D16: =$B$11 | E16: SPLIT:
A17: =$B$8 | B17: =$B$9 | D17: =$B$11 | E17: SPLIT:
A18: =$B$8 | B18: =$B$9 | D18: =$B$11 | E18: SPLIT:
A19: =$B$8 | B19: =$B$9 | D19: =$B$11 | E19: SPLIT:
A21: Sum of splits: | B21: =SUM(F15:F19) -> 0 | C21: Original: | D21: =$B$10 | E21: Difference: | F21: =IFERROR(D21-B21,0) -> 0
A24: RECEIPT ITEMIZATION LOG
A25: (Reference only - does not affect budget calculations)
A27: Date | B27: Store | C27: Item | D27: Qty | E27: Price | F27: Category

Sheet Archive
A1: 📦 ARCHIVED DATA
A2: Historical reference - not actively used in model
A4: HOUSING TRANSITION (Completed Jan 2026)
A5: New Home: 761 E Morningside Dr NE
A6: Closing Date | B6: 1/29/2026
A7: Sale Price | B7: 1180640
A8: Loan Amount | B8: 826448
A9: Interest Rate | B9: 5.5%
A10: Monthly P&I | B10: 4692.48
A11: Monthly Tax/Ins/HOA | B11: 1827.07
A13: Old Home: 980 Rawlins St SE
A14: Expected Sale | B14: April 2026
A15: Est. Net Proceeds | B15: 276000

Sheet Instructions
A1: HOW TO USE THIS WORKBOOK
A3: 📊 STRUCTURE (9 sheets)
A4: Dashboard - All KPIs and strategic overview
A5: Assumptions - Key inputs (blue = editable)
A6: 5-Year Pro Forma - Financial projections with scenarios
A7: Budget vs Actual - Monthly tracking with deep-dives
A8: Balance Sheet - Assets and liabilities
A9: Config - Settings, dates, budgets, CapEx planning
A10: Raw Data - Master transaction data
A11: Import - Paste Monarch exports here
A12: Tools - Split helper and receipt log
A14: 📥 IMPORTING DATA
... A33: - Type column: blank=included, Business=excluded
